<?xml version='1.0'?>

<robot name="my_bot" xmlns:xacro="http://www.ros.org/wiki/xacro">
<xacro:include filename="$(find custom_bot)/urdf/my_bot.gazebo" />
  <link name="robot_footprint"></link>

  <joint name="robot_footprint_joint" type="fixed">
    <origin xyz="0 0 0" rpy="0 0 0" />
    <parent link="robot_footprint"/>
    <child link="chassis" />
  </joint>


  <link name='chassis'>
    <pose>0 0 0.1 0 0 0</pose>

    <inertial>
      <mass value="15.0"/>
      <origin xyz="0.0 0 0" rpy=" 0 0 0"/>
      <inertia
          ixx="0.1" ixy="0" ixz="0"
          iyy="0.1" iyz="0"
          izz="0.1"
      />
    </inertial>

    <collision name='collision'>
      <origin xyz="0 0 0" rpy=" 0 0 0"/> 
      <geometry>
        <box size=".4 .2 .05"/>
      </geometry>
    </collision>

    <visual name='chassis_visual'>
      <origin xyz="0 0 0" rpy=" 0 0 0"/>
      <geometry>
        <box size=".4 .2 .05"/>
      </geometry>
    </visual>

    <collision name='FloorBed_collision'>
      <origin xyz="0 0 0.02" rpy=" 0 0 0"/> 
      <geometry>
        <box size=".5 .3 .01"/>
      </geometry>
    </collision>

    <visual name='FloorBed_visual'>
      <origin xyz="0 0 0.02" rpy=" 0 0 0"/>
      <geometry>
        <box size=".5 .3 .01"/>
      </geometry>
    </visual>

  </link>



  <link name='Left_front_wheel'>

    <inertial>
      <mass value="5.0"/>
      <origin xyz="0 0 0" rpy="0 0 0"/>
      <inertia
          ixx="0.1" ixy="0" ixz="0"
          iyy="0.1" iyz="0"
          izz="0.1"
      />
    </inertial>

    <collision name='collision'>
      <origin xyz="0 0 0" rpy="0 0 1.5707"/> 
      <geometry>
        <mesh filename="package://custom_bot/meshes/wheel.dae"/>
      </geometry>
    </collision>


    <visual name='left_front_wheel_visual'>
      <origin xyz="0 0 0" rpy="0 0 1.5707"/>
      <geometry>
        <mesh filename="package://custom_bot/meshes/wheel.dae"/>
      </geometry>
    </visual>

  </link>

  <joint type="continuous" name="left_front_wheel_hinge">
    <origin xyz="0.15 0.11 -0.1" rpy="0 0 0"/>
    <child link="Left_front_wheel"/>
    <parent link="chassis"/>
    <axis xyz="0 1 0" rpy="0 0 0"/>
    <limit effort="10000" velocity="1000"/>
    <joint_properties damping="1.0" friction="1.0"/>
  </joint>



 
  <link name='Left_back_wheel'>

    <inertial>
      <mass value="5.0"/>
      <origin xyz="0 0 0" rpy="0 0 0"/>
      <inertia
          ixx="0.1" ixy="0" ixz="0"
          iyy="0.1" iyz="0"
          izz="0.1"
      />
    </inertial>

    <collision name='collision'>
      <origin xyz="0 0 0" rpy="0 0 1.5707"/> 
      <geometry>
        <mesh filename="package://custom_bot/meshes/wheel.dae"/>
      </geometry>
    </collision>


    <visual name='left_back_wheel_visual'>
      <origin xyz="0 0 0" rpy="0 0 1.5707"/>
      <geometry>
        <mesh filename="package://custom_bot/meshes/wheel.dae"/>
      </geometry>
    </visual>
  
  </link>

  <joint type="continuous" name="left_back_wheel_hinge">
    <origin xyz="-0.05 0.11 -0.1" rpy="0 0 0"/>
    <child link="Left_back_wheel"/>
    <parent link="chassis"/>
    <axis xyz="0 1 0" rpy="0 0 0"/>
    <limit effort="10000" velocity="1000"/>
    <joint_properties damping="1.0" friction="1.0"/>
  </joint>




  <link name='Right_front_wheel'>

    <inertial>
      <mass value="5.0"/>
      <origin xyz="0 0 0" rpy="0 0 0"/>
      <inertia
          ixx="0.1" ixy="0" ixz="0"
          iyy="0.1" iyz="0"
          izz="0.1"
      />
    </inertial>

    <collision name='collision'>
      <origin xyz="0 0 0" rpy=" 0 0 1.5707"/> 
      <geometry>
        <mesh filename="package://custom_bot/meshes/wheel.dae"/>
      </geometry>
    </collision>


    <visual name='right_front_wheel_visual'>
      <origin xyz="0 0 0" rpy=" 0 0 1.5707"/>
      <geometry>
        <mesh filename="package://custom_bot/meshes/wheel.dae"/>
      </geometry>
    </visual>

  </link>

  <joint type="continuous" name="right_front_wheel_hinge">
    <origin xyz="0.15 -0.15 -0.1" rpy="0 0 0"/>
    <child link="Right_front_wheel"/>
    <parent link="chassis"/>
    <axis xyz="0 1 0" rpy="0 0 0"/>
    <limit effort="10000" velocity="1000"/>
    <joint_properties damping="1.0" friction="1.0"/>
    <transmission name="right_front_wheel_trans" type="SimpleTransmission">
      <type>transmission_interface/SimpleTransmission</type>
      <actuator name="right_front_wheel_motor">
          <mechanicalReduction>1</mechanicalReduction>
      </actuator>
      <joint name="right_front_wheel_hinge">
          <hardwareInterface>VelocityJointInterface</hardwareInterface>
      </joint>
    </transmission>
  </joint>



  <link name='Right_back_wheel'>

    <inertial>
      <mass value="5.0"/>
      <origin xyz="0 0 0" rpy="0 0 0"/>
      <inertia
          ixx="0.1" ixy="0" ixz="0"
          iyy="0.1" iyz="0"
          izz="0.1"
      />
    </inertial>

    <collision name='collision'>
      <origin xyz="0 0 0" rpy=" 0 0 1.5707"/> 
      <geometry>
        <mesh filename="package://custom_bot/meshes/wheel.dae"/>
      </geometry>
    </collision>


    <visual name='right_back_wheel_visual'>
      <origin xyz="0 0 0" rpy=" 0 0 1.5707"/>
      <geometry>
        <mesh filename="package://custom_bot/meshes/wheel.dae"/>
      </geometry>
    </visual>

  </link>

  <joint type="continuous" name="right_back_wheel_hinge">
    <origin xyz="-0.05 -0.15 -0.1" rpy="0 0 0"/>
    <child link="Right_back_wheel"/>
    <parent link="chassis"/>
    <axis xyz="0 1 0" rpy="0 0 0"/>
    <limit effort="10000" velocity="1000"/>
    <joint_properties damping="1.0" friction="1.0"/>
    <transmission name="right_back_wheel_trans" type="SimpleTransmission">
      <type>transmission_interface/SimpleTransmission</type>
      <actuator name="right_back_wheel_motor">
        <mechanicalReduction>1</mechanicalReduction>
      </actuator>
      <joint name="right_back_wheel_hinge">
        <hardwareInterface>VelocityJointInterface</hardwareInterface>
      </joint>
    </transmission>
  </joint>



  <link name='camera'>

    <inertial>
      <mass value="0.0"/>
      <origin xyz="0.0 0 0" rpy="0 0 0"/>
      <inertia
          ixx="1e-6" ixy="0" ixz="0"
          iyy="1e-6" iyz="0"
          izz="1e-6"
      />
    </inertial>

    <collision name='collision'>
      <origin xyz="0 0 0" rpy=" 0 0 0"/> 
      <geometry>
        <box size=".05 .05 .04"/>
      </geometry>
    </collision>

    <visual name='camera_visual'>
      <origin xyz="0 0 0" rpy=" 0 0 0"/>
      <geometry>
        <box size=".07 .05 .04"/>
      </geometry>
    </visual>
  
  </link>

  <joint type="fixed" name="camera_joint">
    <origin xyz="0.24 0 -0.005" rpy="0 0 0"/>
    <child link="camera"/>
    <parent link="chassis"/>
  </joint>




  <link name='hokuyo'>

    <inertial>
      <mass value="0.0"/>
      <origin xyz="0.0 0 0" rpy="0 0 0"/>
      <inertia
          ixx="1e-6" ixy="0" ixz="0"
          iyy="1e-6" iyz="0"
          izz="1e-6"
      />
    </inertial>

    <collision name='collision'>
      <origin xyz="0 0 0" rpy=" 0 0 0"/> 
      <geometry>
        <box size="0.1 0.1 0.1"/>
      </geometry>
    </collision>

    <visual name='laser_visual'>
      <origin xyz="0 0 0" rpy=" 0 0 0"/>
      <geometry>
        <mesh filename="package://udacity_bot/meshes/hokuyo.dae"/>
      </geometry>
    </visual>
  
  </link>

  <joint type="fixed" name="hokuyo_joint">
    <origin xyz="0.22 0 0.05" rpy="0 0 0"/>
    <child link="hokuyo"/>
    <parent link="chassis"/>
  </joint> 


  <gazebo reference="FloorBed_visual">
      <material>Gazebo/Orange</material>
  </gazebo>

  <gazebo reference="camera">
      <material>Gazebo/Blue</material>
  </gazebo>

</robot>
